<html>
<head>
<title>Angular meets RxJS: Error handling</title>
<link href="../Styles/Style.css" type="text/css" rel="stylesheet"/>
</head>
<body>
<h1 class="translated">角度符合RxJS:错误处理</h1>
<blockquote>原文：<a href="https://javascript.plainenglish.io/angular-meets-rxjs-error-handling-8fad48721e49?source=collection_archive---------4-----------------------#2021-03-14">https://javascript.plainenglish.io/angular-meets-rxjs-error-handling-8fad48721e49?source=collection_archive---------4-----------------------#2021-03-14</a></blockquote><div><div class="fc ib ic id ie if"/><div class="ig ih ii ij ik"><div class=""/><figure class="gl gn jl jm jn jo gh gi paragraph-image"><div role="button" tabindex="0" class="jp jq di jr bf js"><div class="gh gi jk"><img src="../Images/e16b48a86c9821f5667ebabae8f9afc9.png" data-original-src="https://miro.medium.com/v2/resize:fit:1400/0*ofbAGUfjT1MFcHnh"/></div></div><figcaption class="jv jw gj gh gi jx jy bd b be z dk">Photo by <a class="ae jz" href="https://unsplash.com/@charlfolscher?utm_source=medium&amp;utm_medium=referral" rel="noopener ugc nofollow" target="_blank">Charl Folscher</a> on <a class="ae jz" href="https://unsplash.com?utm_source=medium&amp;utm_medium=referral" rel="noopener ugc nofollow" target="_blank">Unsplash</a></figcaption></figure><h1 id="98de" class="ka kb in bd kc kd ke kf kg kh ki kj kk kl km kn ko kp kq kr ks kt ku kv kw kx bi translated">介绍</h1><p id="a3e5" class="pw-post-body-paragraph ky kz in la b lb lc ld le lf lg lh li lj lk ll lm ln lo lp lq lr ls lt lu lv ig bi translated">这篇文章属于名为“<strong class="la io"> Angular meets RxJS </strong>”的系列文章，在这篇文章中，我尽我所能在“Angular”上下文中使用“RxJS”来解释反应式编程。</p><h1 id="4806" class="ka kb in bd kc kd ke kf kg kh ki kj kk kl km kn ko kp kq kr ks kt ku kv kw kx bi translated">目录</h1><p id="c804" class="pw-post-body-paragraph ky kz in la b lb lc ld le lf lg lh li lj lk ll lm ln lo lp lq lr ls lt lu lv ig bi translated"><a class="ae jz" rel="noopener ugc nofollow" target="_blank" href="/angular-meets-rxjs-basic-concepts-f178d8fe0e02">基本概念</a> <br/> <a class="ae jz" rel="noopener ugc nofollow" target="_blank" href="/angular-meets-rxjs-rxjs-subjects-32cac1b2c8d3"> RxJS科目</a> <br/> <a class="ae jz" rel="noopener ugc nofollow" target="_blank" href="/angular-meets-rxjs-rxjs-operators-part-1-9e9751a9373e"> RxJS运算符(第1部分)</a> <br/> <a class="ae jz" rel="noopener ugc nofollow" target="_blank" href="/angular-meets-rxjs-rxjs-operators-60d8b2140d20"> RxJS运算符(第2部分)</a> <br/> <a class="ae jz" href="https://ssougnez.medium.com/angular-meets-rxjs-rxjs-operators-e64caa5f72e7" rel="noopener"> RxJS运算符(第3部分)</a><br/><a class="ae jz" rel="noopener ugc nofollow" target="_blank" href="/angular-meets-rxjs-takeuntil-and-the-async-pipe-4d9c6e3d5c2d">“take until”和“async”管道</a> <br/> <a class="ae jz" rel="noopener ugc nofollow" target="_blank" href="/angular-meets-rxjs-higher-order-observables-632e560ce2d0">高阶可观察量</a> <br/>错误处理<br/> RxJS调度器(即将推出)<br/></p><h1 id="6760" class="ka kb in bd kc kd ke kf kg kh ki kj kk kl km kn ko kp kq kr ks kt ku kv kw kx bi translated">在这篇文章中</h1><p id="9ab9" class="pw-post-body-paragraph ky kz in la b lb lc ld le lf lg lh li lj lk ll lm ln lo lp lq lr ls lt lu lv ig bi translated">啊！错误…可能是开发中最容易被忽视的方面之一。我不得不承认，当我构建一个新的应用程序时，我50%的“TODO”都被称为“错误处理”。构建一些东西总是很有趣，但是考虑如何处理应用程序中出现的错误就不那么有趣了。</p><p id="c69d" class="pw-post-body-paragraph ky kz in la b lb lw ld le lf lx lh li lj ly ll lm ln lz lp lq lr ma lt lu lv ig bi translated">然而，使用“RxJS”处理错误是一个非常重要的话题，因为当错误发生时，可观测量如何反应。在这篇文章中，我们将看到处理它们的不同方法。</p><h1 id="f3d0" class="ka kb in bd kc kd ke kf kg kh ki kj kk kl km kn ko kp kq kr ks kt ku kv kw kx bi translated">指导原则</h1><p id="c3af" class="pw-post-body-paragraph ky kz in la b lb lc ld le lf lg lh li lj lk ll lm ln lo lp lq lr ls lt lu lv ig bi translated">如果读完这篇文章后，你只需要记住一件事，那就让这件事过去吧:</p><blockquote class="mb mc md"><p id="307d" class="ky kz me la b lb lw ld le lf lx lh li mf ly ll lm mg lz lp lq mh ma lt lu lv ig bi translated">当一个错误发生时，游戏就结束了，可观察性结束了，你无法从中恢复。</p></blockquote><p id="0993" class="pw-post-body-paragraph ky kz in la b lb lw ld le lf lx lh li lj ly ll lm ln lz lp lq lr ma lt lu lv ig bi translated">让我们用下面的例子来说明:</p><figure class="mi mj mk ml gt jo"><div class="bz fp l di"><div class="mm mn l"/></div></figure><p id="83f6" class="pw-post-body-paragraph ky kz in la b lb lw ld le lf lx lh li lj ly ll lm ln lz lp lq lr ma lt lu lv ig bi translated">这里没什么复杂的，但是，如果你有疑问，去读一读这个系列的第一篇文章。现在，我们可以期待什么样的结果呢？</p><p id="a6b3" class="pw-post-body-paragraph ky kz in la b lb lw ld le lf lx lh li lj ly ll lm ln lz lp lq lr ma lt lu lv ig bi translated">如果您不知道我刚才提到的黄金法则，那么可以合理地假设一些条目会被记录在控制台中，直到“x”达到“5”，然后是一个错误，然后是一些其他条目，直到应用程序结束。然而，正如你所知道的黄金法则，你可能不会对这个结果感到惊讶:</p><figure class="mi mj mk ml gt jo gh gi paragraph-image"><div role="button" tabindex="0" class="jp jq di jr bf js"><div class="gh gi mo"><img src="../Images/286e722deb4e7a832ffa9ce3f6fee913.png" data-original-src="https://miro.medium.com/v2/resize:fit:1400/format:webp/1*WAo6fNzs_uv94Q8EABkOSQ.png"/></div></div></figure><p id="0a85" class="pw-post-body-paragraph ky kz in la b lb lw ld le lf lx lh li lj ly ll lm ln lz lp lq lr ma lt lu lv ig bi translated">正如你所看到的，一旦错误被可观察对象发出，它就结束了，可观察对象停止发出新的值，仅仅因为它被认为是“坏的”或“死的”，无论你喜欢什么。事实上，错误是不应该出现的，并且“RxJS”认为发出错误的可观察对象受到损害，并且不能再被信任来发出一致的值。</p><p id="1d5d" class="pw-post-body-paragraph ky kz in la b lb lw ld le lf lx lh li lj ly ll lm ln lz lp lq lr ma lt lu lv ig bi translated">这意味着一个可观察对象可以完成或发出一个错误，但它不能两者都做。事实上，一旦可观察对象完成，它就不会发出错误，但是当可观察对象发出错误时，就不会调用“完成”回调。</p><p id="cbcc" class="pw-post-body-paragraph ky kz in la b lb lw ld le lf lx lh li lj ly ll lm ln lz lp lq lr ma lt lu lv ig bi translated">现在，让我们看看如何优雅地处理错误。</p><blockquote class="mb mc md"><p id="9768" class="ky kz me la b lb lw ld le lf lx lh li mf ly ll lm mg lz lp lq mh ma lt lu lv ig bi translated">请记住，当它失败时，它就失败了，所以甚至不要尝试谷歌“如何忽略RxJS中的一个错误”，因为这是不可能的，相信我，我试过。</p></blockquote><h1 id="7cf6" class="ka kb in bd kc kd ke kf kg kh ki kj kk kl km kn ko kp kq kr ks kt ku kv kw kx bi translated">错误回调</h1><p id="7df8" class="pw-post-body-paragraph ky kz in la b lb lc ld le lf lg lh li lj lk ll lm ln lo lp lq lr ls lt lu lv ig bi translated">如果您阅读了本系列的第一篇文章，当我说您可以通过提供错误回调来处理错误时，您应该不会感到惊讶。</p><figure class="mi mj mk ml gt jo"><div class="bz fp l di"><div class="mm mn l"/></div></figure><p id="298c" class="pw-post-body-paragraph ky kz in la b lb lw ld le lf lx lh li lj ly ll lm ln lz lp lq lr ma lt lu lv ig bi translated">通过提供这个错误处理程序，您可以“优雅地”处理错误，将它作为警告记录在控制台中。</p><figure class="mi mj mk ml gt jo gh gi paragraph-image"><div role="button" tabindex="0" class="jp jq di jr bf js"><div class="gh gi mo"><img src="../Images/7ef5103fbb47d2c937159bbe30f1b8a5.png" data-original-src="https://miro.medium.com/v2/resize:fit:1400/format:webp/1*xNd7rhQGErKn3xDvqosv6g.png"/></div></div></figure><p id="1122" class="pw-post-body-paragraph ky kz in la b lb lw ld le lf lx lh li lj ly ll lm ln lz lp lq lr ma lt lu lv ig bi translated">然而，正如您在上面看到的，您处理了错误<strong class="la io">的事实并不意味着可观察对象将继续发出值</strong>，这就是为什么即使您处理了异常，也没有记录其他值。</p><h1 id="e288" class="ka kb in bd kc kd ke kf kg kh ki kj kk kl km kn ko kp kq kr ks kt ku kv kw kx bi translated">捕捉错误</h1><p id="1451" class="pw-post-body-paragraph ky kz in la b lb lc ld le lf lg lh li lj lk ll lm ln lo lp lq lr ls lt lu lv ig bi translated">错误回调并不是优雅地处理错误的唯一方式。实际上，您也可以在管道中使用“catchError”操作符来实现这一点。当您构建一个返回可观察对象的函数，但您希望可能的错误由该函数而不是可观察的消费者来处理时，这一点特别有用。</p><p id="27c1" class="pw-post-body-paragraph ky kz in la b lb lw ld le lf lx lh li lj ly ll lm ln lz lp lq lr ma lt lu lv ig bi translated">该操作符允许优雅地处理错误，在某种意义上，它允许您在出现错误时发出“与错误不同的值”，这意味着该操作符必须返回另一个可观察值作为错误“值”。此外，由于可观察对象发出的是替换值而不是错误，因此会调用“完整”回调。让我们来看看下面的例子，把事情弄清楚:</p><figure class="mi mj mk ml gt jo"><div class="bz fp l di"><div class="mm mn l"/></div></figure><p id="77ea" class="pw-post-body-paragraph ky kz in la b lb lw ld le lf lx lh li lj ly ll lm ln lz lp lq lr ma lt lu lv ig bi translated">在这个例子中，我们在可观察管道中添加了“catchError”操作符，以捕捉由源可观察对象抛出的异常。在这种情况下，如果发生这样的事件，“catchError”运算符会用值“-1”替换错误。通过这样做，它通过用一个值替换它来隐藏错误发生的事实，并完成可观察的，这就是为什么此代码的输出如下:</p><figure class="mi mj mk ml gt jo gh gi paragraph-image"><div role="button" tabindex="0" class="jp jq di jr bf js"><div class="gh gi mo"><img src="../Images/863c4eadc2bffe19c0883ca5149087d9.png" data-original-src="https://miro.medium.com/v2/resize:fit:1400/format:webp/1*jZwZPZBhW8BhUEKFX6AvGg.png"/></div></div></figure><p id="fd6d" class="pw-post-body-paragraph ky kz in la b lb lw ld le lf lx lh li lj ly ll lm ln lz lp lq lr ma lt lu lv ig bi translated">这里有三件重要的事情需要注意:</p><ol class=""><li id="bdbb" class="mp mq in la b lb lw lf lx lj mr ln ms lr mt lv mu mv mw mx bi translated">记录条目“-1已收到”，就好像“-1”是由可观察对象发出的常规值一样。</li><li id="6243" class="mp mq in la b lb my lf mz lj na ln nb lr nc lv mu mv mw mx bi translated">不再调用“错误”回调。</li><li id="d7ea" class="mp mq in la b lb my lf mz lj na ln nb lr nc lv mu mv mw mx bi translated">即使发生错误，也会调用“完成”回调。</li></ol><p id="0df7" class="pw-post-body-paragraph ky kz in la b lb lw ld le lf lx lh li lj ly ll lm ln lz lp lq lr ma lt lu lv ig bi translated">所以，再一次也是最后一次，<strong class="la io">我们处理了错误的事实并不意味着可观察对象将继续发出值</strong>。抛出了一个错误，就这样，故事结束了。</p><p id="6dbb" class="pw-post-body-paragraph ky kz in la b lb lw ld le lf lx lh li lj ly ll lm ln lz lp lq lr ma lt lu lv ig bi translated">该运算符的大理石图如下:</p><figure class="mi mj mk ml gt jo gh gi paragraph-image"><div class="gh gi nd"><img src="../Images/c6269d1eed3a1e0d73b5c2cda0ae4492.png" data-original-src="https://miro.medium.com/v2/resize:fit:1000/format:webp/1*PsT5Xe90w2GiTNya-h1vsw.png"/></div></figure><h1 id="5135" class="ka kb in bd kc kd ke kf kg kh ki kj kk kl km kn ko kp kq kr ks kt ku kv kw kx bi translated">投掷误差</h1><p id="dee6" class="pw-post-body-paragraph ky kz in la b lb lc ld le lf lg lh li lj lk ll lm ln lo lp lq lr ls lt lu lv ig bi translated">该操作符不用于处理错误，但在某些情况下可能会派上用场。实际上，在上面的代码中，我们不想混淆错误发生的事实，但是我们想对错误做些什么。换句话说，捕捉错误以便在全局组件中显示消息，然后“传播”错误以便调用“error”回调是有意义的。这可以通过“throwError”操作符来实现，该操作符接受参数中的一个值，并将其作为错误抛出。</p><figure class="mi mj mk ml gt jo"><div class="bz fp l di"><div class="mm mn l"/></div></figure><p id="874b" class="pw-post-body-paragraph ky kz in la b lb lw ld le lf lx lh li lj ly ll lm ln lz lp lq lr ma lt lu lv ig bi translated">这一次，输出有点不同:</p><figure class="mi mj mk ml gt jo gh gi paragraph-image"><div role="button" tabindex="0" class="jp jq di jr bf js"><div class="gh gi mo"><img src="../Images/833c763232e95a91077b1beaae5720f6.png" data-original-src="https://miro.medium.com/v2/resize:fit:1400/format:webp/1*jzwbI99lB3a6Kba6ujI6MQ.png"/></div></div></figure><p id="67b4" class="pw-post-body-paragraph ky kz in la b lb lw ld le lf lx lh li lj ly ll lm ln lz lp lq lr ma lt lu lv ig bi translated">如您所见，通过在控制台中记录警告,“catchError”正确地完成了工作。然而，当我们返回由“throwError”返回的可观察对象时，最初的异常被转发到输出可观察对象，这就是为什么调用“Error”回调而不是“complete”回调的原因。</p><p id="022f" class="pw-post-body-paragraph ky kz in la b lb lw ld le lf lx lh li lj ly ll lm ln lz lp lq lr ma lt lu lv ig bi translated">正如我所说的，在“角度”上下文中，这是一种有效的方法，可以在服务的全局组件中显示消息，同时让使用该函数的组件有机会通过显示服务全局显示的错误或其他内容来本地处理错误。</p><h1 id="1f22" class="ka kb in bd kc kd ke kf kg kh ki kj kk kl km kn ko kp kq kr ks kt ku kv kw kx bi translated">完成</h1><p id="420a" class="pw-post-body-paragraph ky kz in la b lb lc ld le lf lg lh li lj lk ll lm ln lo lp lq lr ls lt lu lv ig bi translated">可以看到“catchError”操作符具有JavaScript的“try { … } catch { … }”结构，因此正如您所料,“finalize”操作符存在于“finally { … }”子句中。当操作符完成或出错时，这个操作符简单地调用一个函数。例如:</p><figure class="mi mj mk ml gt jo"><div class="bz fp l di"><div class="mm mn l"/></div></figure><p id="a4dc" class="pw-post-body-paragraph ky kz in la b lb lw ld le lf lx lh li lj ly ll lm ln lz lp lq lr ma lt lu lv ig bi translated">这里，我们在完成可观测值之前捕捉错误以发出值“-1”。我们还使用“finalize”操作符在控制台中记录一条消息。</p><figure class="mi mj mk ml gt jo gh gi paragraph-image"><div role="button" tabindex="0" class="jp jq di jr bf js"><div class="gh gi mo"><img src="../Images/ac44ff96842411cbecf0397f9529d8b3.png" data-original-src="https://miro.medium.com/v2/resize:fit:1400/format:webp/1*E06RKHsz222N4RUS1-L8xQ.png"/></div></div></figure><p id="8e8c" class="pw-post-body-paragraph ky kz in la b lb lw ld le lf lx lh li lj ly ll lm ln lz lp lq lr ma lt lu lv ig bi translated">我们可以看到，一旦观察完成，就正确地调用了“finalize”。如果我们从“catchError”中抛出一个异常，也会出现这种情况，如“throwError”一节所述。</p><figure class="mi mj mk ml gt jo gh gi paragraph-image"><div role="button" tabindex="0" class="jp jq di jr bf js"><div class="gh gi mo"><img src="../Images/788b5709014d8a25e82ffbc004f8e3a7.png" data-original-src="https://miro.medium.com/v2/resize:fit:1400/format:webp/1*YN6muFo6Zqu2wTy39It4kw.png"/></div></div></figure><h1 id="2e7a" class="ka kb in bd kc kd ke kf kg kh ki kj kk kl km kn ko kp kq kr ks kt ku kv kw kx bi translated">链接</h1><p id="5ff5" class="pw-post-body-paragraph ky kz in la b lb lc ld le lf lg lh li lj lk ll lm ln lo lp lq lr ls lt lu lv ig bi translated">您不局限于管道中的一个“catchError”运算符，例如:</p><figure class="mi mj mk ml gt jo"><div class="bz fp l di"><div class="mm mn l"/></div></figure><blockquote class="mb mc md"><p id="7cf5" class="ky kz me la b lb lw ld le lf lx lh li mf ly ll lm mg lz lp lq mh ma lt lu lv ig bi translated">我为这个蹩脚的代码感到抱歉…在C#(我最喜欢的后端语言)中，我通常用数字除以0来产生错误，但在JavaScript中，这不会产生错误，所以我不得不即兴创作。</p></blockquote><p id="4d92" class="pw-post-body-paragraph ky kz in la b lb lw ld le lf lx lh li lj ly ll lm ln lz lp lq lr ma lt lu lv ig bi translated">在上面的代码中，可观察对象直接发出一个错误，这个错误被第一个“catchError”捕获。这个只是登录到控制台并发出值0。然后是我这辈子输入的最糟糕的代码，它通过调用“null”上的“substring”来创建错误，这就是为什么第二个“catchError”通过捕捉错误并在抛出原始错误之前将某些内容记录到控制台来执行。最后，“finalize”操作符清理一切。</p><figure class="mi mj mk ml gt jo gh gi paragraph-image"><div role="button" tabindex="0" class="jp jq di jr bf js"><div class="gh gi mo"><img src="../Images/bced9106083876b10fe5d13b9388703a.png" data-original-src="https://miro.medium.com/v2/resize:fit:1400/format:webp/1*T0S29TBUz4QBjsDtT3l39w.png"/></div></div></figure><h1 id="972f" class="ka kb in bd kc kd ke kf kg kh ki kj kk kl km kn ko kp kq kr ks kt ku kv kw kx bi translated">重试</h1><figure class="mi mj mk ml gt jo gh gi paragraph-image"><div class="gh gi ne"><img src="../Images/ce173660362ff0e2ae3ffebaef03a028.png" data-original-src="https://miro.medium.com/v2/resize:fit:990/format:webp/1*lWuXDmNHFB278hs4OBDCzw.png"/></div></figure><blockquote class="mb mc md"><p id="4229" class="ky kz me la b lb lw ld le lf lx lh li mf ly ll lm mg lz lp lq mh ma lt lu lv ig bi translated">嘿！但是你说不可能从错误中恢复，现在你又说要重试！</p></blockquote><p id="8d2a" class="pw-post-body-paragraph ky kz in la b lb lw ld le lf lx lh li lj ly ll lm ln lz lp lq lr ma lt lu lv ig bi translated">好吧，我没有说谎，“重试”操作符不能用来简单地重试发出最新的值或什么的。事实上，如果你使用“重试”，你实际上再次订阅了源可观测值，这意味着值将再次开始发出…从头开始。让我们像这样更新我们的例子:</p><figure class="mi mj mk ml gt jo"><div class="bz fp l di"><div class="mm mn l"/></div></figure><p id="3562" class="pw-post-body-paragraph ky kz in la b lb lw ld le lf lx lh li lj ly ll lm ln lz lp lq lr ma lt lu lv ig bi translated">我们更新了我们的可观测值，当“x”等于“5”时发出一个错误，但只有当一个随机数低于0.5(意味着50%的概率)时。下面是一个可能的场景:</p><figure class="mi mj mk ml gt jo gh gi paragraph-image"><div role="button" tabindex="0" class="jp jq di jr bf js"><div class="gh gi mo"><img src="../Images/f993dfb5eb23192a15d05203fe7350d6.png" data-original-src="https://miro.medium.com/v2/resize:fit:1400/format:webp/1*0kReylzrd3Rgc2ub0nMLFA.png"/></div></div></figure><p id="eadd" class="pw-post-body-paragraph ky kz in la b lb lw ld le lf lx lh li lj ly ll lm ln lz lp lq lr ma lt lu lv ig bi translated">这是最好的情况。随机数大于0.5，所以可观测值没有发出错误，从此过上了幸福的生活。然而，也存在当生成的数量低于0.5时的情况:</p><figure class="mi mj mk ml gt jo gh gi paragraph-image"><div role="button" tabindex="0" class="jp jq di jr bf js"><div class="gh gi mo"><img src="../Images/a2cba45230d5c88f581a7fbdef5583e2.png" data-original-src="https://miro.medium.com/v2/resize:fit:1400/format:webp/1*5qtpjmTaVxZMcEjhw2z1xw.png"/></div></div></figure><p id="4dec" class="pw-post-body-paragraph ky kz in la b lb lw ld le lf lx lh li lj ly ll lm ln lz lp lq lr ma lt lu lv ig bi translated">正如我们所看到的，错误没有记录在控制台中，相反，可观察对象被重新订阅，值开始从零开始发出。在这种情况下，第二个生成的数字大于0.5，这解释了为什么第二个订阅发出的值超过4。</p><p id="7cc3" class="pw-post-body-paragraph ky kz in la b lb lw ld le lf lx lh li lj ly ll lm ln lz lp lq lr ma lt lu lv ig bi translated">最后，最后一个场景:</p><figure class="mi mj mk ml gt jo gh gi paragraph-image"><div role="button" tabindex="0" class="jp jq di jr bf js"><div class="gh gi mo"><img src="../Images/42a699777b0ecf4c48eaa1176c31f2e4.png" data-original-src="https://miro.medium.com/v2/resize:fit:1400/format:webp/1*EE40Q4X7XWW0_2cbF8tS_g.png"/></div></div></figure><p id="d057" class="pw-post-body-paragraph ky kz in la b lb lw ld le lf lx lh li lj ly ll lm ln lz lp lq lr ma lt lu lv ig bi translated">在这种情况下，由于两个生成的数字都低于0.5，所以会发出两次错误，这也是可观察对象最终会发出错误的原因。我还没有说出来，但是你可能已经猜到了，传递给“重试”的数字定义了可观察对象被重试的次数。</p><p id="acae" class="pw-post-body-paragraph ky kz in la b lb lw ld le lf lx lh li lj ly ll lm ln lz lp lq lr ma lt lu lv ig bi translated">这里有一个有趣的评论。我一直说“重试”重新订阅源可观察。然后，您可以问自己“间隔是否被正确清除？”。事实证明，的确如此，我们可以证明:</p><figure class="mi mj mk ml gt jo"><div class="bz fp l di"><div class="mm mn l"/></div></figure><p id="bb11" class="pw-post-body-paragraph ky kz in la b lb lw ld le lf lx lh li lj ly ll lm ln lz lp lq lr ma lt lu lv ig bi translated">这一次，当“x”达到“5”时，我们发出错误，并且当调用“取消订阅”函数(清除间隔的函数)时，我们在控制台中记录一些内容。这段代码的输出如下:</p><figure class="mi mj mk ml gt jo gh gi paragraph-image"><div role="button" tabindex="0" class="jp jq di jr bf js"><div class="gh gi mo"><img src="../Images/c5687174b3cfecdb4656174ae3ed2b4d.png" data-original-src="https://miro.medium.com/v2/resize:fit:1400/format:webp/1*EBr3gB2V8IuCNR-LB0wZCw.png"/></div></div></figure><p id="ba33" class="pw-post-body-paragraph ky kz in la b lb lw ld le lf lx lh li lj ly ll lm ln lz lp lq lr ma lt lu lv ig bi translated">选中的行显示“retry”实际上取消订阅源可观察对象，然后再次订阅它，确保可观察对象分配的所有资源都被释放。</p><figure class="mi mj mk ml gt jo gh gi paragraph-image"><div role="button" tabindex="0" class="jp jq di jr bf js"><div class="gh gi nf"><img src="../Images/4aabcba2539f90bec68a25aadc6b697e.png" data-original-src="https://miro.medium.com/v2/resize:fit:1400/format:webp/1*pQCY0vw81Zm-E_SARG9Icw.png"/></div></div></figure><p id="61a5" class="pw-post-body-paragraph ky kz in la b lb lw ld le lf lx lh li lj ly ll lm ln lz lp lq lr ma lt lu lv ig bi translated">请注意，该大理石图说明了两次重试尝试都失败的情况。</p><h1 id="8f27" class="ka kb in bd kc kd ke kf kg kh ki kj kk kl km kn ko kp kq kr ks kt ku kv kw kx bi translated">重试时间</h1><p id="2596" class="pw-post-body-paragraph ky kz in la b lb lc ld le lf lg lh li lj lk ll lm ln lo lp lq lr ls lt lu lv ig bi translated">“retryWhen”运算符有点难以理解。基本上，它的行为与“重试”相似，只是它使用通知可观察对象来确定何时需要重试可观察对象(也就是说，当它需要取消订阅时，然后再次订阅源可观察对象)。让我们从最基本的开始:</p><figure class="mi mj mk ml gt jo"><div class="bz fp l di"><div class="mm mn l"/></div></figure><p id="cba8" class="pw-post-body-paragraph ky kz in la b lb lw ld le lf lx lh li lj ly ll lm ln lz lp lq lr ma lt lu lv ig bi translated">好了，在希望理解这段代码之前，有两件重要的事情需要理解:</p><ol class=""><li id="fa96" class="mp mq in la b lb lw lf lx lj mr ln ms lr mt lv mu mv mw mx bi translated">如果源可观察对象没有发出任何错误，则不会调用传递给“retryWhen”的函数。</li><li id="282a" class="mp mq in la b lb my lf mz lj na ln nb lr nc lv mu mv mw mx bi translated">传递给“retryWhen”的函数<strong class="la io">只被调用一次</strong>，即使源可观察对象在每次重试尝试时发出一个错误。</li></ol><p id="068d" class="pw-post-body-paragraph ky kz in la b lb lw ld le lf lx lh li lj ly ll lm ln lz lp lq lr ma lt lu lv ig bi translated">因此，传递给“retryWhen”的函数的目标是返回一个可观察对象，用于向“retryWhen”指示何时必须取消订阅源可观察对象，然后再次订阅它。这个函数的第一个参数(这里是“错误”)是一个发出被捕获错误的可观察值。</p><p id="f3ef" class="pw-post-body-paragraph ky kz in la b lb lw ld le lf lx lh li lj ly ll lm ln lz lp lq lr ma lt lu lv ig bi translated">我们通常使用这个可观察对象，并通过管道返回通知可观察对象。定义何时重试可观察对象的是输出可观察对象(由“错误”的“管道”返回的对象)。所以基本上，每次输出可观测发射时，源可观测(主要的)被重试。理解这一点很重要，因为这意味着即使没有抛出第二个错误，也可以重试源可观察值。我们稍后会看到这一点，但首先，让我们看看上面代码的输出:</p><figure class="mi mj mk ml gt jo gh gi paragraph-image"><div role="button" tabindex="0" class="jp jq di jr bf js"><div class="gh gi mo"><img src="../Images/b367b72128747adb5080101735cd7964.png" data-original-src="https://miro.medium.com/v2/resize:fit:1400/format:webp/1*QtfHAoXSF8R-yVxtntRtVg.png"/></div></div></figure><p id="a352" class="pw-post-body-paragraph ky kz in la b lb lw ld le lf lx lh li lj ly ll lm ln lz lp lq lr ma lt lu lv ig bi translated">让我们来分解一下:</p><ul class=""><li id="756b" class="mp mq in la b lb lw lf lx lj mr ln ms lr mt lv ng mv mw mx bi translated">首先，值被正确地发出。</li><li id="ccef" class="mp mq in la b lb my lf mz lj na ln nb lr nc lv ng mv mw mx bi translated">当“x”达到“5”时，会抛出一个错误。</li><li id="06ab" class="mp mq in la b lb my lf mz lj na ln nb lr nc lv ng mv mw mx bi translated">这样做的直接后果是“retryWhen”被执行(如日志所示)。</li><li id="c509" class="mp mq in la b lb my lf mz lj na ln nb lr nc lv ng mv mw mx bi translated">“retryWhen”的执行导致通知可观察对象的创建，该通知可观察对象定义了何时重试源可观察对象。换句话说，只要新创建的通知可观察对象发出一个值，就会重试源可观察对象。</li><li id="e29b" class="mp mq in la b lb my lf mz lj na ln nb lr nc lv ng mv mw mx bi translated">在我们的例子中，通知可观察对象使用“tap”操作符记录错误，然后将输入可观察对象(“错误”)的值转发给通知可观察对象(输出)。</li><li id="edd3" class="mp mq in la b lb my lf mz lj na ln nb lr nc lv ng mv mw mx bi translated">这意味着通知可观察对象一创建就发出一个值，从而导致源可观察对象的重试，这就是再次发出值“0”的原因。</li><li id="d94b" class="mp mq in la b lb my lf mz lj na ln nb lr nc lv ng mv mw mx bi translated">源可观测值再次发出。</li><li id="a69d" class="mp mq in la b lb my lf mz lj na ln nb lr nc lv ng mv mw mx bi translated">当“x”达到“5”时，会抛出一个错误。</li><li id="ccac" class="mp mq in la b lb my lf mz lj na ln nb lr nc lv ng mv mw mx bi translated"><strong class="la io">如您所见，这一次，称“retryWhen”被调用的条目没有被记录到控制台。我们说过，传递给“retryWhen”的函数只被调用一次。</strong></li><li id="cfdc" class="mp mq in la b lb my lf mz lj na ln nb lr nc lv ng mv mw mx bi translated">然而，抛出的错误实际上是在名为“错误”的可观察对象上发出的，因此被转发给通知可观察对象(因为它是从“错误”可观察对象中创建的)。</li><li id="ec7a" class="mp mq in la b lb my lf mz lj na ln nb lr nc lv ng mv mw mx bi translated">因此，通知可观察对象再次在控制台中记录错误(通过“tap”)，然后发出错误，导致源可观察对象被重试。</li><li id="d87f" class="mp mq in la b lb my lf mz lj na ln nb lr nc lv ng mv mw mx bi translated">如此等等…</li></ul><p id="07cb" class="pw-post-body-paragraph ky kz in la b lb lw ld le lf lx lh li lj ly ll lm ln lz lp lq lr ma lt lu lv ig bi translated">我还没有说的是，您可以通过完成通知observable来阻止“retryWhen”重试。例如:</p><figure class="mi mj mk ml gt jo"><div class="bz fp l di"><div class="mm mn l"/></div></figure><p id="d1b5" class="pw-post-body-paragraph ky kz in la b lb lw ld le lf lx lh li lj ly ll lm ln lz lp lq lr ma lt lu lv ig bi translated">在这种情况下，一旦在可观察的错误上发出了两个值，我们就完成了可观察的通知，这意味着可观察的通知将只重试一次。事实上，当发出第一个错误时，可观察对象被重试，然而，当发出第二个错误时，通知可观察对象完成，因此，主输出可观察对象也完成。</p><figure class="mi mj mk ml gt jo gh gi paragraph-image"><div role="button" tabindex="0" class="jp jq di jr bf js"><div class="gh gi mo"><img src="../Images/ed7ecb886ac0012f22b395ed75c5a628.png" data-original-src="https://miro.medium.com/v2/resize:fit:1400/format:webp/1*bHptUmBfNuco1uvnbhq9aQ.png"/></div></div></figure><p id="1c13" class="pw-post-body-paragraph ky kz in la b lb lw ld le lf lx lh li lj ly ll lm ln lz lp lq lr ma lt lu lv ig bi translated">现在，让我们看最后一个(不好的)例子，以确保你理解这个操作符。</p><figure class="mi mj mk ml gt jo"><div class="bz fp l di"><div class="mm mn l"/></div></figure><h1 id="6765" class="ka kb in bd kc kd ke kf kg kh ki kj kk kl km kn ko kp kq kr ks kt ku kv kw kx bi translated">注意，这个代码是错误的，不能使用。</h1><p id="30b6" class="pw-post-body-paragraph ky kz in la b lb lc ld le lf lg lh li lj lk ll lm ln lo lp lq lr ls lt lu lv ig bi translated">这里，我们没有从“错误”返回一个可观测值，而是创建一个每2.5秒发出一次的全新的可观测值。这是错误的，因为这意味着这个可观察对象与“错误”对象完全不相关，所以如果在这个可观察对象上抛出并发出错误，通知对象不会意识到它，因为它是不相关的。</p><p id="353f" class="pw-post-body-paragraph ky kz in la b lb lw ld le lf lx lh li lj ly ll lm ln lz lp lq lr ma lt lu lv ig bi translated">它是错误的第二个原因(是第一个原因的结果)是，无论发生什么，可观察到的通知每2.5秒发出一次。这意味着在第一次错误后，主源观测实际上将每2.5秒重试一次。</p><figure class="mi mj mk ml gt jo gh gi paragraph-image"><div role="button" tabindex="0" class="jp jq di jr bf js"><div class="gh gi mo"><img src="../Images/bbd4c04a5dd3fba95eadbb31ed786352.png" data-original-src="https://miro.medium.com/v2/resize:fit:1400/format:webp/1*aS2Frrag9lPr1sL23oUP9Q.png"/></div></div></figure><p id="1879" class="pw-post-body-paragraph ky kz in la b lb lw ld le lf lx lh li lj ly ll lm ln lz lp lq lr ma lt lu lv ig bi translated">您可以在上面的控制台中看到这一点。虽然没有引发任何错误，但这些值是正确发出的。然后，当抛出第一个错误时，通知可观察对象被创建，然后在2.5秒后发出一个值，导致源可观察对象被重试，因此这些值开始再次发出。然而，2.5秒后，通知observable发出一个新值，导致主源observable被重试，即使它没有抛出第二个错误。如果你想在一段时间后重试源观测，那么简单地使用“延迟”可能更好。</p><figure class="mi mj mk ml gt jo"><div class="bz fp l di"><div class="mm mn l"/></div></figure><h1 id="5f09" class="ka kb in bd kc kd ke kf kg kh ki kj kk kl km kn ko kp kq kr ks kt ku kv kw kx bi translated">最后的想法</h1><p id="51b2" class="pw-post-body-paragraph ky kz in la b lb lc ld le lf lg lh li lj lk ll lm ln lo lp lq lr ls lt lu lv ig bi translated">尽管这并不有趣，但是处理错误对于一个高质量的应用程序来说是一个非常重要的标准。事实上，当应用程序中发生错误时，您必须相应地警告用户，并尝试以最好的方式恢复。</p><p id="4e5a" class="pw-post-body-paragraph ky kz in la b lb lw ld le lf lx lh li lj ly ll lm ln lz lp lq lr ma lt lu lv ig bi translated">在下一篇文章中，我们将看到什么是“RxJS”调度器，以及如何使用它们来更精确地控制observables何时发出它们的值。</p><figure class="mi mj mk ml gt jo gh gi paragraph-image"><a href="https://www.buymeacoffee.com/ssougnez"><div class="gh gi nh"><img src="../Images/6d60b235fcc46a4bd696b90e886419ee.png" data-original-src="https://miro.medium.com/v2/resize:fit:340/format:webp/1*Dpw8-hNGI2fDmosV4E8DVQ.png"/></div></a></figure></div></div>    
</body>
</html>